// Wrapper function to catch errors in async route handlers
const catchAsync = (fn) => {
  return (req, res, next) => {
    Promise.resolve(fn(req, res, next)).catch(next);
  };
};

module.exports = catchAsync;
